Workbook

Sheet 1.CLV CalcuLation
A1: CUSTUMER_ID | B1: Purchases Per Custumer | C1: Total revenue(List_prie) | D1: Average of Custumer Lifespan(tenure) | E1: CLV | F1: job_industry_category | G1: WEALTH SEGMENT
A2: 1 | B2: 11 | C2: 9084.45 | D2: 11 | E2: =B2*C2*D2 -> 1099218.4 | F2: =VLOOKUP('1.CLV CalcuLation'!A2,Customer_Demographic__2[],8,FALSE) -> Health | G2: =VLOOKUP(A2,Customer_Demographic__2[#All],9,FALSE) -> Mass Customer
A3: 2 | B3: 3 | C3: 4149.07 | D3: 16 | E3: =B3*C3*D3 -> 199155.36 | F3: =VLOOKUP('1.CLV CalcuLation'!A3,Customer_Demographic__2[],8,FALSE) -> Financial Services | G3: =VLOOKUP(A3,Customer_Demographic__2[#All],9,FALSE) -> Mass Customer
A4: 3 | B4: 7 | C4: 9525.22 | D4: 15 | E4: =B4*C4*D4 -> 1000148.1 | F4: =VLOOKUP('1.CLV CalcuLation'!A4,Customer_Demographic__2[],8,FALSE) -> Property | G4: =VLOOKUP(A4,Customer_Demographic__2[#All],9,FALSE) -> Mass Customer
A5: 4 | B5: 2 | C5: 1047.72 | D5: 7 | E5: =B5*C5*D5 -> 14668.08 | F5: =VLOOKUP('1.CLV CalcuLation'!A5,Customer_Demographic__2[],8,FALSE) -> IT | G5: =VLOOKUP(A5,Customer_Demographic__2[#All],9,FALSE) -> Mass Customer
A6: 5 | B6: 6 | C6: 5903.2 | D6: 8 | E6: =B6*C6*D6 -> 283353.6 | F6: =VLOOKUP('1.CLV CalcuLation'!A6,Customer_Demographic__2[],8,FALSE) -> Others | G6: =VLOOKUP(A6,Customer_Demographic__2[#All],9,FALSE) -> Affluent Customer
A7: 6 | B7: 5 | C7: 5931.69 | D7: 13 | E7: =B7*C7*D7 -> 385559.85 | F7: =VLOOKUP('1.CLV CalcuLation'!A7,Customer_Demographic__2[],8,FALSE) -> Retail | G7: =VLOOKUP(A7,Customer_Demographic__2[#All],9,FALSE) -> High Net Worth
A8: 7 | B8: 3 | C8: 995.38 | D8: 11 | E8: =B8*C8*D8 -> 32847.54 | F8: =VLOOKUP('1.CLV CalcuLation'!A8,Customer_Demographic__2[],8,FALSE) -> Financial Services | G8: =VLOOKUP(A8,Customer_Demographic__2[#All],9,FALSE) -> Affluent Customer
A9: 8 | B9: 9 | C9: 9933.29 | D9: 7 | E9: =B9*C9*D9 -> 625797.27 | F9: =VLOOKUP('1.CLV CalcuLation'!A9,Customer_Demographic__2[],8,FALSE) -> Others | G9: =VLOOKUP(A9,Customer_Demographic__2[#All],9,FALSE) -> Mass Customer
A10: 9 | B10: 6 | C10: 5357.55 | D10: 8 | E10: =B10*C10*D10 -> 257162.4 | F10: =VLOOKUP('1.CLV CalcuLation'!A10,Customer_Demographic__2[],8,FALSE) -> Argiculture | G10: =VLOOKUP(A10,Customer_Demographic__2[#All],9,FALSE) -> Affluent Customer
A11: 10 | B11: 5 | C11: 5003.75 | D11: 20 | E11: =B11*C11*D11 -> 500375 | F11: =VLOOKUP('1.CLV CalcuLation'!A11,Customer_Demographic__2[],8,FALSE) -> Financial Services | G11: =VLOOKUP(A11,Customer_Demographic__2[#All],9,FALSE) -> Mass Customer
A12: 11 | B12: 5 | C12: 6026.8 | D12: 9 | E12: =B12*C12*D12 -> 271206 | F12: =VLOOKUP('1.CLV CalcuLation'!A12,Customer_Demographic__2[],8,FALSE) -> Property | G12: =VLOOKUP(A12,Customer_Demographic__2[#All],9,FALSE) -> Mass Customer
A13: 12 | B13: 7 | C13: 6394.21 | D13: 8 | E13: =B13*C13*D13 -> 358075.76 | F13: =VLOOKUP('1.CLV CalcuLation'!A13,Customer_Demographic__2[],8,FALSE) -> Manufacturing | G13: =VLOOKUP(A13,Customer_Demographic__2[#All],9,FALSE) -> Mass Customer
... A144: 143 | B144: 4 | C144: 4689.21 | D144: 11 | E144: =B144*C144*D144 -> 206325.24 | F144: =VLOOKUP('1.CLV CalcuLation'!A144,Customer_Demographic__2[],8,FALSE) -> Argiculture | G144: =VLOOKUP(A144,Customer_Demographic__2[#All],9,FALSE) -> Mass Customer
A145: 144 | B145: 8 | C145: 8961.14 | E145: =B145*C145*D145 -> 0 | F145: =VLOOKUP('1.CLV CalcuLation'!A145,Customer_Demographic__2[],8,FALSE) -> IT | G145: =VLOOKUP(A145,Customer_Demographic__2[#All],9,FALSE) -> Mass Customer
A146: 145 | B146: 7 | C146: 8149.19 | D146: 4 | E146: =B146*C146*D146 -> 228177.32 | F146: =VLOOKUP('1.CLV CalcuLation'!A146,Customer_Demographic__2[],8,FALSE) -> Financial Services | G146: =VLOOKUP(A146,Customer_Demographic__2[#All],9,FALSE) -> Mass Customer
A147: 146 | B147: 2 | C147: 1973.29 | D147: 8 | E147: =B147*C147*D147 -> 31572.64 | F147: =VLOOKUP('1.CLV CalcuLation'!A147,Customer_Demographic__2[],8,FALSE) -> Manufacturing | G147: =VLOOKUP(A147,Customer_Demographic__2[#All],9,FALSE) -> Mass Customer
A148: 147 | B148: 6 | C148: 8079.09 | D148: 10 | E148: =B148*C148*D148 -> 484745.4 | F148: =VLOOKUP('1.CLV CalcuLation'!A148,Customer_Demographic__2[],8,FALSE) -> Health | G148: =VLOOKUP(A148,Customer_Demographic__2[#All],9,FALSE) -> Mass Customer
A149: 148 | B149: 5 | C149: 5808.83 | D149: 5 | E149: =B149*C149*D149 -> 145220.75 | F149: =VLOOKUP('1.CLV CalcuLation'!A149,Customer_Demographic__2[],8,FALSE) -> Others | G149: =VLOOKUP(A149,Customer_Demographic__2[#All],9,FALSE) -> Mass Customer
A150: 149 | B150: 4 | C150: 4945.69 | D150: 1 | E150: =B150*C150*D150 -> 19782.76 | F150: =VLOOKUP('1.CLV CalcuLation'!A150,Customer_Demographic__2[],8,FALSE) -> Health | G150: =VLOOKUP(A150,Customer_Demographic__2[#All],9,FALSE) -> Mass Customer
A151: 150 | B151: 4 | C151: 3630.96 | D151: 17 | E151: =B151*C151*D151 -> 246905.28 | F151: =VLOOKUP('1.CLV CalcuLation'!A151,Customer_Demographic__2[],8,FALSE) -> Financial Services | G151: =VLOOKUP(A151,Customer_Demographic__2[#All],9,FALSE) -> Affluent Customer
A152: 151 | B152: 7 | C152: 11422.85 | D152: 13 | E152: =B152*C152*D152 -> 1039479.3 | F152: =VLOOKUP('1.CLV CalcuLation'!A152,Customer_Demographic__2[],8,FALSE) -> Manufacturing | G152: =VLOOKUP(A152,Customer_Demographic__2[#All],9,FALSE) -> Mass Customer
A153: 152 | B153: 2 | C153: 2941.37 | D153: 16 | E153: =B153*C153*D153 -> 94123.84 | F153: =VLOOKUP('1.CLV CalcuLation'!A153,Customer_Demographic__2[],8,FALSE) -> Financial Services | G153: =VLOOKUP(A153,Customer_Demographic__2[#All],9,FALSE) -> Mass Customer
A154: 153 | B154: 7 | C154: 7808.16 | D154: 12 | E154: =B154*C154*D154 -> 655885.44 | F154: =VLOOKUP('1.CLV CalcuLation'!A154,Customer_Demographic__2[],8,FALSE) -> Entertainment | G154: =VLOOKUP(A154,Customer_Demographic__2[#All],9,FALSE) -> Mass Customer
A155: 154 | B155: 5 | C155: 3521.53 | D155: 11 | E155: =B155*C155*D155 -> 193684.15 | F155: =VLOOKUP('1.CLV CalcuLation'!A155,Customer_Demographic__2[],8,FALSE) -> Others | G155: =VLOOKUP(A155,Customer_Demographic__2[#All],9,FALSE) -> Mass Customer
A156: 155 | B156: 3 | C156: 4008.51 | D156: 10 | E156: =B156*C156*D156 -> 120255.3 | F156: =VLOOKUP('1.CLV CalcuLation'!A156,Customer_Demographic__2[],8,FALSE) -> Manufacturing | G156: =VLOOKUP(A156,Customer_Demographic__2[#All],9,FALSE) -> Mass Customer
A157: 156 | B157: 5 | C157: 4831.58 | D157: 11 | E157: =B157*C157*D157 -> 265736.9 | F157: =VLOOKUP('1.CLV CalcuLation'!A157,Customer_Demographic__2[],8,FALSE) -> Financial Services | G157: =VLOOKUP(A157,Customer_Demographic__2[#All],9,FALSE) -> Mass Customer
... A168: 167 | B168: 9 | C168: 9888.61 | D168: 17 | E168: =B168*C168*D168 -> 1512957.3 | F168: =VLOOKUP('1.CLV CalcuLation'!A168,Customer_Demographic__2[],8,FALSE) -> Health | G168: =VLOOKUP(A168,Customer_Demographic__2[#All],9,FALSE) -> High Net Worth
A169: 168 | B169: 8 | C169: 8563.42 | E169: =B169*C169*D169 -> 0 | F169: =VLOOKUP('1.CLV CalcuLation'!A169,Customer_Demographic__2[],8,FALSE) -> IT | G169: =VLOOKUP(A169,Customer_Demographic__2[#All],9,FALSE) -> Affluent Customer
A170: 169 | B170: 3 | C170: 2065.08 | D170: 5 | E170: =B170*C170*D170 -> 30976.2 | F170: =VLOOKUP('1.CLV CalcuLation'!A170,Customer_Demographic__2[],8,FALSE) -> Telecommunications | G170: =VLOOKUP(A170,Customer_Demographic__2[#All],9,FALSE) -> High Net Worth
A171: 170 | B171: 3 | C171: 3684.75 | D171: 21 | E171: =B171*C171*D171 -> 232139.25 | F171: =VLOOKUP('1.CLV CalcuLation'!A171,Customer_Demographic__2[],8,FALSE) -> Health | G171: =VLOOKUP(A171,Customer_Demographic__2[#All],9,FALSE) -> High Net Worth
A172: 171 | B172: 8 | C172: 9347.85 | D172: 10 | E172: =B172*C172*D172 -> 747828 | F172: =VLOOKUP('1.CLV CalcuLation'!A172,Customer_Demographic__2[],8,FALSE) -> Manufacturing | G172: =VLOOKUP(A172,Customer_Demographic__2[#All],9,FALSE) -> Mass Customer
A173: 172 | B173: 7 | C173: 9250.22 | D173: 6 | E173: =B173*C173*D173 -> 388509.24 | F173: =VLOOKUP('1.CLV CalcuLation'!A173,Customer_Demographic__2[],8,FALSE) -> Manufacturing | G173: =VLOOKUP(A173,Customer_Demographic__2[#All],9,FALSE) -> Affluent Customer
A174: 173 | B174: 9 | C174: 14061.48 | D174: 1 | E174: =B174*C174*D174 -> 126553.32 | F174: =VLOOKUP('1.CLV CalcuLation'!A174,Customer_Demographic__2[],8,FALSE) -> Health | G174: =VLOOKUP(A174,Customer_Demographic__2[#All],9,FALSE) -> Affluent Customer
A175: 174 | B175: 10 | C175: 12893.57 | D175: 12 | E175: =B175*C175*D175 -> 1547228.4 | F175: =VLOOKUP('1.CLV CalcuLation'!A175,Customer_Demographic__2[],8,FALSE) -> Health | G175: =VLOOKUP(A175,Customer_Demographic__2[#All],9,FALSE) -> Mass Customer
A176: 175 | B176: 5 | C176: 6008.03 | D176: 5 | E176: =B176*C176*D176 -> 150200.75 | F176: =VLOOKUP('1.CLV CalcuLation'!A176,Customer_Demographic__2[],8,FALSE) -> Manufacturing | G176: =VLOOKUP(A176,Customer_Demographic__2[#All],9,FALSE) -> Affluent Customer
A177: 176 | B177: 4 | C177: 6146.7 | D177: 10 | E177: =B177*C177*D177 -> 245868 | F177: =VLOOKUP('1.CLV CalcuLation'!A177,Customer_Demographic__2[],8,FALSE) -> Property | G177: =VLOOKUP(A177,Customer_Demographic__2[#All],9,FALSE) -> Mass Customer
A178: 177 | B178: 12 | C178: 11826.34 | D178: 4 | E178: =B178*C178*D178 -> 567664.32 | F178: =VLOOKUP('1.CLV CalcuLation'!A178,Customer_Demographic__2[],8,FALSE) -> Financial Services | G178: =VLOOKUP(A178,Customer_Demographic__2[#All],9,FALSE) -> High Net Worth
A179: 178 | B179: 4 | C179: 3504.09 | D179: 8 | E179: =B179*C179*D179 -> 112130.88 | F179: =VLOOKUP('1.CLV CalcuLation'!A179,Customer_Demographic__2[],8,FALSE) -> Others | G179: =VLOOKUP(A179,Customer_Demographic__2[#All],9,FALSE) -> Affluent Customer
A180: 179 | B180: 3 | C180: 3168.84 | D180: 6 | E180: =B180*C180*D180 -> 57039.12 | F180: =VLOOKUP('1.CLV CalcuLation'!A180,Customer_Demographic__2[],8,FALSE) -> Manufacturing | G180: =VLOOKUP(A180,Customer_Demographic__2[#All],9,FALSE) -> High Net Worth
...

Sheet 2.SEGMENT CLV ANALYSIS
A3: JOB INDUSRY | B3: Average of CLV
A4: Argiculture | B4: 408680.22
A5: Entertainment | B5: 475657.46
A6: Financial Services | B6: 407181.76
A7: Health | B7: 450292.99
A8: IT | B8: 294016.79
A9: Manufacturing | B9: 413403
A10: Others | B10: 407028.19
A11: Property | B11: 455789.14
A12: Retail | B12: 438432.52
A13: Telecommunications | B13: 467514.08
A22: Average CLV by Wealth_segment.
A25: WEALTH SEGMENT | B25: Average of CLV
A26: Affluent Customer | B26: 407290.27
A27: High Net Worth | B27: 422150.53
A28: Mass Customer | B28: 421746.78
A30: https://drive.google.com/file/d/11NQURvgi4zJizwh10H34IeSEk6Zaxt0W/view?usp=sharing

Sheet Customer_Demographic_2
A1: customer_id | B1: first_name | C1: last_name | D1: gender | E1: past_3_years_bike_related_purchases | F1: DOB | G1: job_title | H1: job_industry_category | I1: wealth_segment | J1: deceased_indicator | K1: owns_car | L1: tenure
A2: 1 | B2: Laraine | C2: Medendorp | D2: F | E2: 93 | F2: 19644 | G2: Executive Secretary | H2: Health | I2: Mass Customer | J2: N | K2: Yes | L2: 11
A3: 2 | B3: Eli | C3: Bockman | D3: Male | E3: 81 | F3: 29571 | G3: Administrative Officer | H3: Financial Services | I3: Mass Customer | J3: N | K3: Yes | L3: 16
A4: 3 | B4: Arlin | C4: Dearle | D4: Male | E4: 61 | F4: 19744 | G4: Recruiting Manager | H4: Property | I4: Mass Customer | J4: N | K4: Yes | L4: 15
A5: 4 | B5: Talbot | D5: Male | E5: 33 | F5: 22557 | G5: Others | H5: IT | I5: Mass Customer | J5: N | K5: No | L5: 7
A6: 5 | B6: Sheila-kathryn | C6: Calton | D6: Female | E6: 56 | F6: 28258 | G6: Senior Editor | H6: Others | I6: Affluent Customer | J6: N | K6: Yes | L6: 8
A7: 6 | B7: Curr | C7: Duckhouse | D7: Male | E7: 35 | F7: 24366 | G7: Others | H7: Retail | I7: High Net Worth | J7: N | K7: Yes | L7: 13
A8: 7 | B8: Fina | C8: Merali | D8: Female | E8: 6 | F8: 27813 | G8: Others | H8: Financial Services | I8: Affluent Customer | J8: N | K8: Yes | L8: 11
A9: 8 | B9: Rod | C9: Inder | D9: Male | E9: 31 | F9: 22735 | G9: Media Manager I | H9: Others | I9: Mass Customer | J9: N | K9: No | L9: 7
A10: 9 | B10: Mala | C10: Lind | D10: Female | E10: 97 | F10: 26733 | G10: Business Systems Development Analyst | H10: Argiculture | I10: Affluent Customer | J10: N | K10: Yes | L10: 8
A11: 10 | B11: Fiorenze | C11: Birdall | D11: Female | E11: 49 | F11: 32427 | G11: Senior Quality Engineer | H11: Financial Services | I11: Mass Customer | J11: N | K11: Yes | L11: 20
A12: 11 | B12: Uriah | C12: Bisatt | D12: Male | E12: 99 | F12: 19844 | G12: Others | H12: Property | I12: Mass Customer | J12: N | K12: No | L12: 9
A13: 12 | B13: Sawyere | C13: Flattman | D13: Male | E13: 58 | F13: 34536 | G13: Nuclear Power Engineer | H13: Manufacturing | I13: Mass Customer | J13: N | K13: No | L13: 8
A14: 13 | B14: Gabriele | C14: Norcross | D14: Male | E14: 38 | F14: 20135 | G14: Developer I | H14: Financial Services | I14: High Net Worth | J14: N | K14: Yes | L14: 8
A15: 14 | B15: Rayshell | C15: Kitteman | D15: Female | E15: 85 | F15: 30400 | G15: Account Executive | H15: Financial Services | I15: Affluent Customer | J15: N | K15: No | L15: 6
A16: 15 | B16: Erroll | C16: Radage | D16: Male | E16: 91 | F16: 36720 | G16: Junior Executive | H16: Manufacturing | I16: Mass Customer | J16: N | K16: No | L16: 1
A17: 16 | B17: Harlin | C17: Parr | D17: Male | E17: 38 | F17: 28183 | G17: Media Manager IV | H17: Others | I17: Mass Customer | J17: N | K17: Yes | L17: 18
... A67: 66 | B67: Anselm | C67: Gawne | D67: Male | E67: 46 | F67: 37326 | G67: Account Executive | H67: Argiculture | I67: High Net Worth | J67: N | K67: No | L67: 1
A68: 67 | B68: Vernon | D68: Male | E68: 67 | F68: 22081 | G68: Web Developer II | H68: Retail | I68: Mass Customer | J68: N | K68: No | L68: 18
A69: 68 | B69: Dahlia | C69: Eddoes | D69: Female | E69: 37 | F69: 27140 | G69: Information Systems Manager | H69: Others | I69: Affluent Customer | J69: N | K69: No | L69: 9
A70: 69 | B70: Heidi | C70: Milner | D70: Female | E70: 16 | F70: 25376 | G70: Web Developer II | H70: Others | I70: Mass Customer | J70: N | K70: No | L70: 6
A71: 70 | B71: Foster | C71: Vannoort | D71: Male | E71: 78 | F71: 34027 | G71: Paralegal | H71: Financial Services | I71: Affluent Customer | J71: N | K71: No | L71: 8
A72: 71 | B72: Hoyt | C72: Glavias | D72: Male | E72: 30 | F72: 31074 | G72: Research Associate | H72: Argiculture | I72: Affluent Customer | J72: N | K72: Yes | L72: 12
A73: 72 | B73: Sammy | C73: Cheese | D73: Male | E73: 93 | F73: 26342 | G73: Administrative Officer | H73: Manufacturing | I73: Affluent Customer | J73: N | K73: Yes | L73: 16
A74: 73 | B74: Minette | C74: Worters | D74: Female | E74: 16 | F74: 22063 | G74: Teacher | H74: Others | I74: Affluent Customer | J74: N | K74: Yes | L74: 5
A75: 74 | B75: Pansy | C75: Kiddie | D75: Female | E75: 94 | F75: 25373 | G75: Others | H75: Others | I75: Mass Customer | J75: N | K75: Yes | L75: 6
A76: 75 | B76: Dollie | C76: Sealy | D76: Female | E76: 28 | F76: 28686 | G76: VP Product Management | H76: Property | I76: Mass Customer | J76: N | K76: No | L76: 19
A77: 76 | B77: Rea | C77: Hasser | D77: Female | E77: 20 | F77: 28513 | G77: Statistician II | H77: Retail | I77: High Net Worth | J77: N | K77: Yes | L77: 18
A78: 77 | B78: Shermie | C78: Andrin | D78: Male | E78: 79 | F78: 32763 | G78: Automation Specialist IV | H78: Financial Services | I78: Mass Customer | J78: N | K78: No | L78: 7
A79: 78 | B79: Arch | C79: Van der Kruis | D79: Male | E79: 37 | F79: 31118 | G79: Business Systems Development Analyst | H79: Argiculture | I79: Affluent Customer | J79: N | K79: No | L79: 8
A80: 79 | B80: Tybi | C80: Silliman | D80: Female | E80: 76 | F80: 25113 | G80: Account Executive | H80: Manufacturing | I80: Mass Customer | J80: N | K80: No | L80: 18
... A106: 105 | B106: Maribeth | C106: Pristnor | D106: Female | E106: 25 | F106: 37151 | G106: Recruiting Manager | H106: Manufacturing | I106: Mass Customer | J106: N | K106: No | L106: 1
A107: 106 | B107: Glyn | D107: Male | E107: 54 | F107: 24291 | G107: Software Test Engineer III | H107: Health | I107: High Net Worth | J107: N | K107: Yes | L107: 18
A108: 107 | B108: Pris | C108: Stallebrass | D108: Female | E108: 97 | F108: 33055 | G108: Nurse Practicioner | H108: Financial Services | I108: Mass Customer | J108: N | K108: Yes | L108: 9
A109: 108 | B109: Kayle | C109: Mingaud | D109: Female | E109: 4 | F109: 34407 | G109: Others | H109: Others | I109: High Net Worth | J109: N | K109: No | L109: 3
A110: 109 | B110: Cody | C110: Blabey | D110: Male | E110: 16 | F110: 28835 | G110: Marketing Assistant | H110: Others | I110: Affluent Customer | J110: N | K110: Yes | L110: 4
A111: 110 | B111: Sascha | C111: St. Quintin | D111: Male | E111: 23 | F111: 36738 | G111: Others | H111: Financial Services | I111: Affluent Customer | J111: N | K111: No | L111: 1
A112: 111 | B112: Cele | C112: Evason | D112: Female | E112: 65 | F112: 34210 | G112: Analyst Programmer | H112: Others | I112: Mass Customer | J112: N | K112: No | L112: 2
A113: 112 | B113: Shena | C113: Parren | D113: Female | E113: 88 | F113: 27618 | G113: Marketing Manager | H113: Retail | I113: High Net Worth | J113: N | K113: No | L113: 12
A114: 113 | B114: Gage | C114: Nickless | D114: Male | E114: 67 | F114: 20581 | G114: Staff Scientist | H114: Others | I114: Mass Customer | J114: N | K114: No | L114: 20
...
